---
title: 错误机制处理
category:
date: 2018-11-23 17:05:34
---

> <sup>这里是我读[《阮一峰 JavaScript 教程》](https://wangdoc.com/javascript/)做的笔记。</sup>

## Error 实例对象

JavaScript 解析或运行时，一旦发生错误，引擎就会抛出一个错误对象。JavaScript 原生提供 Error 构造函数，所有抛出错误都是这个构造函数的实例。

```js
var error = new Error('出错啦')
error.message // "出错啦"
```

Error 构造函数接受一个参数，表示错误提示，可以从实例的 message 属性读到这个参数。抛出 Error 实例对象以后，整个程序就中断在发生错误的地方，不再往下执行。

JavaScript 语言标准只提到，Error 实例对象必须有 message 属性，表示出错时的提示信息，没有提到其他属性。大多数 JavaScript 引擎，对 Error 实例还提供 name 和 stack 属性，分别表示错误的名称和错误的堆栈，但他们是非标准的，不是每种实现都有。

使用 name 和 message 可以对发生什么错误有一个大概的了解

```js
if (error.name) {
  console.log(error.name + ':' + error.message)
}
```

stack 属性用来查看错误发生时的堆栈

```js
function throwit() {
  throw new Error('');
}
function catchit() {
  try{
    throwit()
  } catch(e) {
    console.log(e.stack)
  }
}
catchit()
// Error
// at throwit (~/..../throwcatch.js:9:11)
// at catchit (~/..../throwcatch.js:3:9)
// at repl:1:5
```

上面代码中，错误堆栈的最内层是 throwit 函数，然后是 catchit 函数，最后是函数运行的环境。

## 原生错误类型

Error 实例对象是最一般的错误类型，在它的基础上，JavaScript 还定义了其他 6 种错误对象。也就是说存在 6 个派生对象。

### SyntaxError 对象

是解析代码时发生的语法错误

### ReferenceError 对象

是在引用一个不存在的变量时发生的错误，还有将一个值分配给无法分配的对象，比如对函数的运行结果或者 this 赋值。

### RangeError 对象

是一个值超出有效范围时发生的错误。主要有几种情况，一是数组长度为负数，二是 Number 对象的方法参数超出范围，以及函数堆栈超过最大值。

### TypeError 对象

是变量或参数不是预期类型时发生的错误。比如，对字符串、布尔值、数值等原始类型的值使用 new 命令，就会抛出这种错误，因为 new 命令的参数应该是一个构造函数。

### URIError 对象

是对 URI 相关函数的参数不正确时抛出的错误，主要涉及 encodeURI、decodeURI、encodeURIComponent、decodeURIComponent、escape 和 unescape 函数

### EvalError 对象

eval 函数没有被正确执行是，会抛出 EvalError 错误。该错误类型已经不再使用了，只是为了保证与一起代码兼容。

## 自定义错误

除了 JavaScript 原生提供的 7 种错误对象，还可以定义自己的错误对象。

```js
function UserError(message) {
  this.message = message || '默认信息'
  this.name = 'UserError'
}
UserError.prototype = new Error()
UserError.prototype.constructor = UserError;
```

## throw 语句

throw 语句的作用是手动中断程序执行，抛出一个错误。

```js
if (x <= 0) {
  throw new Error('x 必须是正数')
}
```

throw 可以抛出任何类型的值。也就是说，它的参数可以是任何值。

遇到 throw 语句，程序就会中止。引擎会接收到 throw 抛出的信息，可能是一个错误实例，也可能是其他类型的值。

## try...catch 结构

一旦发生错误，程序中止执行。JavaScript 提供了 try...catch 结构允许对错误进行处理，选择是否往下执行。

```js
try {
  throw new Error('出错啦')
} catch (e) {
  console.log(e.name + ':' + e.message)
  console.log(e.stack)
}
```

try 代码块抛出错误，JavaScript 引擎就立即把代码的执行转到 catch 代码块，或者说错误被 catch 代码块捕获到了。catch 接受一个参数，表示 try 代码块抛出的值。

如果你不确定某些代码是否会报错，就可以把他们放在 try...catch 代码块之中，便于进一步对错误进行处理。

```js
try {
  f()
} catch(e) {
  // 处理错误
}
```

如果函数 f 函数执行报错，就会执行 catch 代码块，接着对错误进行处理

catch 代码块捕获错误之后，程序不会中断，会按照正常流程继续执行下去。

catch 代码块之中还可以再抛出错误，甚至使用嵌套的 try...catch 结构。

```js
var n = 100;

try {
  throw n;
} catch (e) {
  if (e <= 50) {
    // ...
  } else {
    throw e;
  }
}
// Uncaught 100
```

catch 代码块之中可以加入判断语句捕获不同类型的错误

```js
try {
  foo.bar();
} catch (e) {
  if (e instanceof EvalError) {
    console.log(e.name + ": " + e.message);
  } else if (e instanceof RangeError) {
    console.log(e.name + ": " + e.message);
  }
  // ...
}
```

## finally 代码块

try...catch 结构允许在最后添加一个 finally 代码块，表示不管是否出错，都必需在最后运行的语句。

```js
function cleansUp() {
  try {
    throw new Error('出错了....')
    console.log('此行不会执行')
  } finally {
    console.log('完成清理工作')
  }
}

cleansUp()
// 完成清理工作
// Uncaught Error: 出错了....
//    at cleansUp (<anonymous>:3:11)
//    at <anonymous>:10:1
```

如果 try 代码块没有发生错误，而且 try 代码块没有发生错误，而且里面还包括 return 语句，但是 finially 代码块依然会执行。而且，这个函数的返回值还是 result。

```js
function idle(x) {
  try {
    console.log(x);
    return 'result';
  } finally {
    console.log('FINALLY');
  }
}

idle('hello')
// hello
// FINALLY
// "result"
```

return 语句的执行是排在 finally 代码之前，只是等 finally 代码执行完毕之后才返回。

```js
var count = 0
function countUp() {
  try {
    return count
  } finally {
    count++
  }
}
countUp()
// 0
count
// 1
```

下面的例子充分反映了 try...catch...finally 这三者之间的执行顺序。

```js
function f() {
  try {
    console.log(0)
    throw 'bug'
  } catch(e) {
    console.log(1)
    return true // 这句原本会延迟到 finally 代码块结束后再执行
    console.log(2)
  } finally {
    console.log(3)
    return false // 有意思，会覆盖掉前面的 return
    console.log(4)
  }
  console.log(5) // 因为有了上面的 return，所以这句不会执行
}
```

